{
 "cells": [
  {
   "cell_type": "code",
   "execution_count": 1,
   "id": "8b4330d4-6241-4b73-bd9a-d7b935bfeb3c",
   "metadata": {},
   "outputs": [],
   "source": [
    "import pandas as pd"
   ]
  },
  {
   "cell_type": "code",
   "execution_count": 2,
   "id": "6fba5ee0-316d-458f-a3b3-a3747cb9b1dc",
   "metadata": {},
   "outputs": [],
   "source": [
    "from pandas import Series"
   ]
  },
  {
   "cell_type": "code",
   "execution_count": 3,
   "id": "54def9c1-c905-4597-b9ec-a0e44226c80d",
   "metadata": {},
   "outputs": [],
   "source": [
    "s = Series([10,20,30,40,50])"
   ]
  },
  {
   "cell_type": "code",
   "execution_count": 4,
   "id": "dc85a0b3-d99a-4462-85c8-0d0826985edd",
   "metadata": {},
   "outputs": [
    {
     "data": {
      "text/plain": [
       "0    10\n",
       "1    20\n",
       "2    30\n",
       "3    40\n",
       "4    50\n",
       "dtype: int64"
      ]
     },
     "execution_count": 4,
     "metadata": {},
     "output_type": "execute_result"
    }
   ],
   "source": [
    "s"
   ]
  },
  {
   "cell_type": "code",
   "execution_count": 5,
   "id": "0b275b97-c234-4a1d-bd13-462149de1e05",
   "metadata": {},
   "outputs": [
    {
     "data": {
      "text/plain": [
       "10"
      ]
     },
     "execution_count": 5,
     "metadata": {},
     "output_type": "execute_result"
    }
   ],
   "source": [
    "s[0]"
   ]
  },
  {
   "cell_type": "code",
   "execution_count": 6,
   "id": "c7fe86ce-f26b-4dfe-b3e4-d9b2733af494",
   "metadata": {},
   "outputs": [
    {
     "data": {
      "text/plain": [
       "numpy.int64"
      ]
     },
     "execution_count": 6,
     "metadata": {},
     "output_type": "execute_result"
    }
   ],
   "source": [
    "type(s[0])"
   ]
  },
  {
   "cell_type": "code",
   "execution_count": 7,
   "id": "ebb444d8-0fb0-4fb6-a264-6c2c7db8c3bd",
   "metadata": {},
   "outputs": [
    {
     "ename": "KeyError",
     "evalue": "-1",
     "output_type": "error",
     "traceback": [
      "\u001b[0;31m---------------------------------------------------------------------------\u001b[0m",
      "\u001b[0;31mValueError\u001b[0m                                Traceback (most recent call last)",
      "File \u001b[0;32m~/.pyenv/versions/3.12.3/lib/python3.12/site-packages/pandas/core/indexes/range.py:413\u001b[0m, in \u001b[0;36mRangeIndex.get_loc\u001b[0;34m(self, key)\u001b[0m\n\u001b[1;32m    412\u001b[0m \u001b[38;5;28;01mtry\u001b[39;00m:\n\u001b[0;32m--> 413\u001b[0m     \u001b[38;5;28;01mreturn\u001b[39;00m \u001b[38;5;28;43mself\u001b[39;49m\u001b[38;5;241;43m.\u001b[39;49m\u001b[43m_range\u001b[49m\u001b[38;5;241;43m.\u001b[39;49m\u001b[43mindex\u001b[49m\u001b[43m(\u001b[49m\u001b[43mnew_key\u001b[49m\u001b[43m)\u001b[49m\n\u001b[1;32m    414\u001b[0m \u001b[38;5;28;01mexcept\u001b[39;00m \u001b[38;5;167;01mValueError\u001b[39;00m \u001b[38;5;28;01mas\u001b[39;00m err:\n",
      "\u001b[0;31mValueError\u001b[0m: -1 is not in range",
      "\nThe above exception was the direct cause of the following exception:\n",
      "\u001b[0;31mKeyError\u001b[0m                                  Traceback (most recent call last)",
      "Cell \u001b[0;32mIn[7], line 1\u001b[0m\n\u001b[0;32m----> 1\u001b[0m \u001b[43ms\u001b[49m\u001b[43m[\u001b[49m\u001b[38;5;241;43m-\u001b[39;49m\u001b[38;5;241;43m1\u001b[39;49m\u001b[43m]\u001b[49m \u001b[38;5;66;03m# can I get final value\u001b[39;00m\n",
      "File \u001b[0;32m~/.pyenv/versions/3.12.3/lib/python3.12/site-packages/pandas/core/series.py:1121\u001b[0m, in \u001b[0;36mSeries.__getitem__\u001b[0;34m(self, key)\u001b[0m\n\u001b[1;32m   1118\u001b[0m     \u001b[38;5;28;01mreturn\u001b[39;00m \u001b[38;5;28mself\u001b[39m\u001b[38;5;241m.\u001b[39m_values[key]\n\u001b[1;32m   1120\u001b[0m \u001b[38;5;28;01melif\u001b[39;00m key_is_scalar:\n\u001b[0;32m-> 1121\u001b[0m     \u001b[38;5;28;01mreturn\u001b[39;00m \u001b[38;5;28;43mself\u001b[39;49m\u001b[38;5;241;43m.\u001b[39;49m\u001b[43m_get_value\u001b[49m\u001b[43m(\u001b[49m\u001b[43mkey\u001b[49m\u001b[43m)\u001b[49m\n\u001b[1;32m   1123\u001b[0m \u001b[38;5;66;03m# Convert generator to list before going through hashable part\u001b[39;00m\n\u001b[1;32m   1124\u001b[0m \u001b[38;5;66;03m# (We will iterate through the generator there to check for slices)\u001b[39;00m\n\u001b[1;32m   1125\u001b[0m \u001b[38;5;28;01mif\u001b[39;00m is_iterator(key):\n",
      "File \u001b[0;32m~/.pyenv/versions/3.12.3/lib/python3.12/site-packages/pandas/core/series.py:1237\u001b[0m, in \u001b[0;36mSeries._get_value\u001b[0;34m(self, label, takeable)\u001b[0m\n\u001b[1;32m   1234\u001b[0m     \u001b[38;5;28;01mreturn\u001b[39;00m \u001b[38;5;28mself\u001b[39m\u001b[38;5;241m.\u001b[39m_values[label]\n\u001b[1;32m   1236\u001b[0m \u001b[38;5;66;03m# Similar to Index.get_value, but we do not fall back to positional\u001b[39;00m\n\u001b[0;32m-> 1237\u001b[0m loc \u001b[38;5;241m=\u001b[39m \u001b[38;5;28;43mself\u001b[39;49m\u001b[38;5;241;43m.\u001b[39;49m\u001b[43mindex\u001b[49m\u001b[38;5;241;43m.\u001b[39;49m\u001b[43mget_loc\u001b[49m\u001b[43m(\u001b[49m\u001b[43mlabel\u001b[49m\u001b[43m)\u001b[49m\n\u001b[1;32m   1239\u001b[0m \u001b[38;5;28;01mif\u001b[39;00m is_integer(loc):\n\u001b[1;32m   1240\u001b[0m     \u001b[38;5;28;01mreturn\u001b[39;00m \u001b[38;5;28mself\u001b[39m\u001b[38;5;241m.\u001b[39m_values[loc]\n",
      "File \u001b[0;32m~/.pyenv/versions/3.12.3/lib/python3.12/site-packages/pandas/core/indexes/range.py:415\u001b[0m, in \u001b[0;36mRangeIndex.get_loc\u001b[0;34m(self, key)\u001b[0m\n\u001b[1;32m    413\u001b[0m         \u001b[38;5;28;01mreturn\u001b[39;00m \u001b[38;5;28mself\u001b[39m\u001b[38;5;241m.\u001b[39m_range\u001b[38;5;241m.\u001b[39mindex(new_key)\n\u001b[1;32m    414\u001b[0m     \u001b[38;5;28;01mexcept\u001b[39;00m \u001b[38;5;167;01mValueError\u001b[39;00m \u001b[38;5;28;01mas\u001b[39;00m err:\n\u001b[0;32m--> 415\u001b[0m         \u001b[38;5;28;01mraise\u001b[39;00m \u001b[38;5;167;01mKeyError\u001b[39;00m(key) \u001b[38;5;28;01mfrom\u001b[39;00m \u001b[38;5;21;01merr\u001b[39;00m\n\u001b[1;32m    416\u001b[0m \u001b[38;5;28;01mif\u001b[39;00m \u001b[38;5;28misinstance\u001b[39m(key, Hashable):\n\u001b[1;32m    417\u001b[0m     \u001b[38;5;28;01mraise\u001b[39;00m \u001b[38;5;167;01mKeyError\u001b[39;00m(key)\n",
      "\u001b[0;31mKeyError\u001b[0m: -1"
     ]
    }
   ],
   "source": [
    "s[-1] # can I get final value"
   ]
  },
  {
   "cell_type": "code",
   "execution_count": 8,
   "id": "6cd591fe-97c2-4393-8cb0-a411bb3ac0f4",
   "metadata": {},
   "outputs": [],
   "source": [
    "# Don't use '[]' by themselves on a series!\n"
   ]
  },
  {
   "cell_type": "code",
   "execution_count": null,
   "id": "c3280411-b553-4d0a-870d-430cff0be5e1",
   "metadata": {},
   "outputs": [],
   "source": []
  }
 ],
 "metadata": {
  "kernelspec": {
   "display_name": "Python 3 (ipykernel)",
   "language": "python",
   "name": "python3"
  },
  "language_info": {
   "codemirror_mode": {
    "name": "ipython",
    "version": 3
   },
   "file_extension": ".py",
   "mimetype": "text/x-python",
   "name": "python",
   "nbconvert_exporter": "python",
   "pygments_lexer": "ipython3",
   "version": "3.12.3"
  }
 },
 "nbformat": 4,
 "nbformat_minor": 5
}
